Workbook

Sheet Tables & Calculations
A1: Number of rides by user type (casual vs member)
A2: user type | B2: Number of rides | C2: Percentage
A3: casual | B3: 2000084 | C3: =B3/SUM($B$3:$B$4) -> 0.36024159
A4: member | B4: 3551979 | C4: =B4/SUM($B$3:$B$4) -> 0.63975841
A6: Number of rides by bike type
A7: bike type | B7: Number of rides | C7: Percentage | D7: Total
A8: classic_bike | B8: 1942384 | C8: =B8/SUM($B$8:$B$9) -> 0.34984906 | D8: 5552063
A9: electric_bike | B9: 3609679 | C9: =B9/SUM($B$8:$B$9) -> 0.65015094
A11: Number of rides by bike type for each user type
A12: user type | B12: bike type | C12: Number of rides | D12: Percentage | E12: Total
A13: casual | B13: electric_bike | C13: 1328141 | D13: =C13/SUM($C$13:$C$14) -> 0.66404261 | E13: 5552063
A14: casual | B14: classic_bike | C14: 671943 | D14: =C14/SUM($C$13:$C$14) -> 0.33595739
A15: member | B15: electric_bike | C15: 2281538 | D15: =C15/SUM($C$15:$C$16) -> 0.64232868
A16: member | B16: classic_bike | C16: 1270441 | D16: =C16/SUM($C$15:$C$16) -> 0.35767132
A18: Average ride duration by user type after excluding rides longer than 150 minutes
A19: user type | B19: Average ride duration | C19: outliers
A20: casual | B20: 17.28 | C20: 0.0039433991
A21: member | B21: 11.45
A23: Ride Duration Distribution by User Type
A24: user type | B24: Ride Duration Distribution | C24: Number of rides | D24: Percentage
A25: casual | B25: 0-10 | C25: 881537 | D25: =C25/SUM($C$25:$C$28) -> 0.44424427
A26: casual | B26: 10-20 | C26: 579858 | D26: =C26/SUM($C$25:$C$28) -> 0.29221529
A27: casual | B27: 20-40 | C27: 344899 | D27: =C27/SUM($C$25:$C$28) -> 0.17380938
A28: casual | B28: 40+ | C28: 178058 | D28: =C28/SUM($C$25:$C$28) -> 0.089731056
A29: member | B29: 0-10 | C29: 2050690 | D29: =C29/SUM($C$29:$C$32) -> 0.57834062
A30: member | B30: 10-20 | C30: 1006769 | D30: =C30/SUM($C$29:$C$32) -> 0.28393146
A31: member | B31: 20-40 | C31: 414677 | D31: =C31/SUM($C$29:$C$32) -> 0.11694822
A32: member | B32: 40+ | C32: 73681 | D32: =C32/SUM($C$29:$C$32) -> 0.020779696
A34: Number of rides by hour of day for each user type | G34: hour comparison using time blocks
A35: user type | B35: hour of day | C35: Number of rides | D35: Percentage | G35: user type | H35: time blocks | I35: Number of rides | J35: Percentage
A36: casual | B36: 0 | C36: 38891 | D36: 0.019444683 | G36: casual | H36: Morning | I36: =SUM('Tables & Calculations'!C42:C46) -> 303306 | J36: =I36/SUM('Tables & Calculations'!$C$36:$C$59) -> 0.15164663
A37: casual | B37: 1 | C37: 24873 | D37: 0.012435978 | G37: casual | H37: Afternoon | I37: =SUM('Tables & Calculations'!C47:C52) -> 839009 | J37: =I37/SUM('Tables & Calculations'!$C$36:$C$59) -> 0.41948688
A38: casual | B38: 2 | C38: 16687 | D38: 0.0083431496 | G38: casual | H38: Evening | I38: =SUM('Tables & Calculations'!C53:C57) -> 639683 | J38: =I38/SUM('Tables & Calculations'!$C$36:$C$59) -> 0.31982807
A39: casual | B39: 3 | C39: 9253 | D39: 0.0046263057 | G39: casual | H39: Night | I39: =SUM('Tables & Calculations'!C58:C59,'Tables & Calculations'!C36:C41) -> 218086 | J39: =I39/SUM('Tables & Calculations'!$C$36:$C$59) -> 0.10903842
A40: casual | B40: 4 | C40: 7280 | D40: 0.0036398471 | G40: member | H40: Morning | I40: =SUM('Tables & Calculations'!C66:C70) -> 867606 | J40: =I40/SUM('Tables & Calculations'!$C$60:$C$83) -> 0.24425989
A41: casual | B41: 5 | C41: 11521 | D41: 0.0057602581 | G41: member | H41: Afternoon | I41: =SUM('Tables & Calculations'!C71:C76) -> 1302808 | J41: =I41/SUM('Tables & Calculations'!$C$60:$C$83) -> 0.3667837
A42: casual | B42: 6 | C42: 26632 | D42: 0.013315441 | G42: member | H42: Evening | I42: =SUM('Tables & Calculations'!C77:C81) -> 1134927 | J42: =I42/SUM('Tables & Calculations'!$C$60:$C$83) -> 0.31951963
A43: casual | B43: 7 | C43: 49693 | D43: 0.024845456 | G43: member | H43: Night | I43: =SUM('Tables & Calculations'!C82:C83,'Tables & Calculations'!C60:C65) -> 246638 | J43: =I43/SUM('Tables & Calculations'!$C$60:$C$83) -> 0.069436784
A44: casual | B44: 8 | C44: 70563 | D44: 0.035280018
A45: casual | B45: 9 | C45: 70889 | D45: 0.035443011
...

Sheet user & bike type
A1: Number of rides by user type (casual vs member)
A2: user type | B2: Number of rides | C2: Percentage
A3: casual | B3: 2000084 | C3: =B3/SUM($B$3:$B$4) -> 0.36024159
A4: member | B4: 3551979 | C4: =B4/SUM($B$3:$B$4) -> 0.63975841

Sheet Visualizations

Sheet Average ride duration 
A2: user type | B2: Average ride duration
A3: casual | B3: 17.28
A4: member | B4: 11.45
A7: Ride Duration Distribution | B7: casual | C7: member
A8: 0-10 min | B8: 0.44424427 | C8: 0.57834062
A9: 10-20 min | B9: 0.29221529 | C9: 0.28393146
A10: 20-40 min | B10: 0.17380938 | C10: 0.11694822
A11: 40+ min | B11: 0.089731056 | C11: 0.020779696

Sheet rides by hour of day 
B1: Morning | C1: Afternoon | D1: Evening | E1: Night
A2: casual | B2: 16.036539 | C2: 19.652495 | D2: 16.061702 | E2: 13.5168
A3: member | B3: 10.536838 | C3: 11.752223 | D3: 11.940965 | E3: 10.897185
B5: 0 | C5: 1 | D5: 2 | E5: 3 | F5: 4 | G5: 5 | H5: 6 | I5: 7 | J5: 8 | K5: 9 | L5: 10 | M5: 11 | N5: 12 | O5: 13 | P5: 14 | Q5: 15 | R5: 16 | S5: 17 | T5: 18 | U5: 19 | V5: 20 | W5: 21 | X5: 22 | Y5: 23
A6: casual | B6: 0.019444683 | C6: 0.012435978 | D6: 0.0083431496 | E6: 0.0046263057 | F6: 0.0036398471 | G6: 0.0057602581 | H6: 0.013315441 | I6: 0.024845456 | J6: 0.035280018 | K6: 0.035443011 | L6: 0.042762704 | M6: 0.054662204 | N6: 0.064336798 | O6: 0.065933231 | P6: 0.069460083 | Q6: 0.07714826 | R6: 0.087946306 | S6: 0.095367495 | T6: 0.081944558 | U6: 0.060966939 | V6: 0.043959154 | W6: 0.037589921 | X6: 0.031765666 | Y6: 0.023022533
A7: member | B7: 0.0091250539 | C7: 0.0056284117 | D7: 0.0034031733 | E7: 0.0022243938 | F7: 0.0024884719 | G7: 0.0096571517 | H7: 0.028425562 | I7: 0.056232314 | J7: 0.072334606 | K7: 0.046939185 | L7: 0.040328223 | M7: 0.047324323 | N7: 0.053554934 | O7: 0.05206506 | P7: 0.052861799 | Q7: 0.066765597 | R7: 0.094211987 | S7: 0.10761212 | T7: 0.083305954 | U7: 0.057583674 | V7: 0.03987608 | W7: 0.031141794 | X7: 0.022718884 | Y7: 0.014191244

Sheet Number of rides by day of week 
B1: Weekday | C1: Weekend
A2: casual | B2: 15.974432 | C2: 19.490756
A3: member | B3: 11.14306 | C3: 12.482659
B5: SUN | C5: MON | D5: TUE | E5: WED | F5: THU | G5: FRI | H5: SAT
A6: casual | B6: 0.16622302 | C6: 0.11440719 | D6: 0.11353473 | E6: 0.11025337 | F6: 0.1286371 | G6: 0.15997578 | H6: 0.20696881
A7: member | B7: 0.10758284 | C7: 0.14199183 | D7: 0.1602394 | E7: 0.15446544 | F7: 0.16080641 | G7: 0.14849497 | H7: 0.1264191

Sheet rides by month 
B1: casual | C1: member
A2: Spring | B2: 17.002608 | C2: 10.921436
A3: Summer | B3: 18.7804 | C3: 12.37337
A4: Fall | B4: 15.966412 | C4: 11.370606
A5: Winter | B5: 10.55651 | C5: 9.5888149
B7: JAN | C7: FEB | D7: MAR | E7: APR | F7: MAY | G7: JUN | H7: JUL | I7: AUG | J7: SEP | K7: OCT | L7: NOV | M7: DEC
A8: casual | B8: 0.01237048 | C8: 0.013877917 | D8: 0.042929197 | E8: 0.054617206 | F8: 0.091381162 | G8: 0.14599687 | H8: 0.16166921 | I8: 0.1689319 | J8: 0.13262843 | K8: 0.1120143 | L8: 0.049538919 | M8: 0.01404441
A9: member | B9: 0.031823668 | C9: 0.034950657 | D9: 0.059760488 | E9: 0.073800267 | F9: 0.090046985 | G9: 0.10889563 | H9: 0.12390445 | I9: 0.1273766 | J9: 0.12649118 | K9: 0.11882334 | L9: 0.072466926 | M9: 0.031659816
